{"metadata":{"language_info":{"codemirror_mode":"text/x-c++src","file_extension":".cpp","mimetype":"text/x-c++src","name":"c++","version":"11"},"kernelspec":{"name":"xcpp11","display_name":"C++11","language":"C++11"}},"nbformat_minor":5,"nbformat":4,"cells":[{"cell_type":"markdown","source":"Existe diferença entre lançar um erro e tratar. Na função abaixo, ao ser chamada a mesma lança um erro atraves da keyword throw","metadata":{},"id":"0d8c070c-614c-42a8-9099-77fcce7833ff"},{"cell_type":"code","source":"#include <iostream>\n\nvoid WentWrong();","metadata":{"trusted":true},"execution_count":1,"outputs":[],"id":"0a3e0422-283c-4660-abc6-ef273b3bbba1"},{"cell_type":"code","source":"void WentWrong()\n{\n    throw 1;\n}\nWentWrong();","metadata":{"trusted":true},"execution_count":2,"outputs":[{"ename":"Error","evalue":"","traceback":["Error: "],"output_type":"error"}],"id":"14dc3e64-a975-455c-b84a-98d550ab03c2"},{"cell_type":"markdown","source":"Se executarmos o codigo acima, veremos que *simplesmente* receberemos um erro.No trecho de codigo abaixo vemos como tratar uma exceção","metadata":{},"id":"3af8ae21-5509-4447-b1a2-b509f5446fc3"},{"cell_type":"code","source":"try {\n    WentWrong();\n}\ncatch(int code)\n{\n    std::cout<<\"You got a error with code: \"<<code<<std::endl;\n}","metadata":{"trusted":true},"execution_count":3,"outputs":[{"name":"stdout","text":"You got a error with code: 1\n","output_type":"stream"}],"id":"5f92105e-6feb-424d-8c71-587956bce9ab"},{"cell_type":"markdown","source":"Note que o que está entre parenteses no catch é um objeto do mesmo tipo lançado na função WentWrong. O que acontece se o objeto de exceção no bloco catch recebido é diferente do esperado? Veremos isso abaixo:","metadata":{},"id":"40c0c6ea-8cd4-4020-8f0b-75555bd7f11b"},{"cell_type":"code","source":"try {\n    WentWrong();\n}\ncatch(char const* code)\n{\n    std::cout<<\"You got a error with code: \"<<code<<std::endl;\n}","metadata":{"trusted":true},"execution_count":4,"outputs":[{"ename":"Error","evalue":"","traceback":["Error: "],"output_type":"error"}],"id":"699e915e-ef05-4168-9842-0b945a391955"},{"cell_type":"markdown","source":"Nesse caso, a função WentWrong() está lançando um objeto de erro do tipo **int** e o tratamento no catch espera um **char const**,com isso, programa terminará com um erro inesperado. Podemos tratar vários tipos de exceção com vários blocos catch para cada objeto de erro. Vejamos o exemplo abaixo:","metadata":{},"id":"344776d6-9e11-419e-b547-6892dbb80865"},{"cell_type":"code","source":"try {\n    WentWrong();\n}\ncatch(char const* erroCode)\n{\n    std::cout<<\"You got a error with code: \"<<erroCode<<std::endl;\n}\ncatch(int erroCode)\n{\n    std::cout<<\"You got a error with code(int): \"<< erroCode <<std::endl;\n}","metadata":{"trusted":true},"execution_count":5,"outputs":[{"name":"stdout","text":"You got a error with code(int): 1\n","output_type":"stream"}],"id":"fd41fee0-b309-46a4-9e05-48c2553e20b5"},{"cell_type":"markdown","source":"O lançamento de uma exceção percorre toda a stack de funções até que se encontre um tratamento apropriado para aquele objeto lançada. Caso não encontre, o programa irá terminar com um erro. Outro aspecto importante do tratamento de exceções é que a criação dos objetos lançados funcionam de uma forma diferente do comum, sempre tais objetos, embora sejam criados dentro de algum escopo de alguma função, serão enxergados nos escopos da call stack. Portanto, é boa prática utilizar o operador & dentro do catch., Vejamos um exemplo interessante ","metadata":{},"id":"3f0220ae-8e41-4cf1-876a-fa824a88b78d"},{"cell_type":"code","source":"#include <iostream>\n\nclass Error{\n    std::string message;\npublic:\n    Error();\n    Error(const Error& error);\n    std::string GetMessage() const;\n};","metadata":{"tags":[],"trusted":true},"execution_count":1,"outputs":[],"id":"0be5ff06-82c5-4fb1-83c3-efefa92737dd"},{"cell_type":"code","source":"Error::Error()\n{\n    message = std::string(\"Mensagem de erro\");\n}","metadata":{"trusted":true},"execution_count":2,"outputs":[],"id":"46a214e8-354e-45e5-81d3-81cd2182b178"},{"cell_type":"code","source":"Error::Error(const Error& e)\n{\n    std::cout<<\"Copy constructor\"<<std::endl;\n}","metadata":{"trusted":true},"execution_count":3,"outputs":[],"id":"25f13bca-7701-434c-9d42-a4b1846d0349"},{"cell_type":"code","source":"std::string Error::GetMessage() const\n{\n    return message;\n}","metadata":{"trusted":true},"execution_count":4,"outputs":[],"id":"20bc1638-96a6-4082-b650-c3e78a8e0806"},{"cell_type":"code","source":"void WentWrong2()\n{\n    throw Error();\n}\n\nWentWrong2();","metadata":{"trusted":true},"execution_count":5,"outputs":[{"ename":"Error","evalue":"","traceback":["Error: "],"output_type":"error"}],"id":"cd49414c-d118-4c59-9bba-64021eddcde5"},{"cell_type":"code","source":"try{\n    WentWrong2();\n}\ncatch(Error e)\n{\n    std::cout<<\"Erro tratado!\"<<e.GetMessage()<<std::endl;\n}","metadata":{"trusted":true},"execution_count":7,"outputs":[{"name":"stdout","text":"Copy constructor\nErro tratado!\n","output_type":"stream"}],"id":"389b82c1-19f2-46f4-a366-3eed92491fff"},{"cell_type":"code","source":"try{\n    WentWrong2();\n}\ncatch(Error& e)\n{\n    std::cout<<\"Erro tratado!\"<<std::endl;\n}","metadata":{"trusted":true},"execution_count":null,"outputs":[],"id":"d1718987-70ad-42e7-87bb-aef6f5db88d7"},{"cell_type":"markdown","source":"Criamos uma classe de exceção chamada Error que guarda uma mensagem de erro. Para essa classe criamos um copy constructor que ao ser chamado escreve uma mensagem chamada *copy constructor*. Na primeira vez que chamamos o catch passando dentro dos parenteses uma copia, o copy constructor foi chamado. Na segunda vez, como o objeto de erro era uma referencia, não foi feita uma copia do construtor e confirmamos isso a vermos que tal mensagem não foi escrita na tela.","metadata":{},"id":"07c8d9bb-a09a-44f6-9648-26651720142e"},{"cell_type":"code","source":"#include <exception>\nclass MyException: public std::exception\n{\n    virtual const char* what() const throw()\n    {\n        return \"Deu bão não\";\n    }\n};","metadata":{"trusted":true},"execution_count":null,"outputs":[],"id":"3ec15f35-6de4-4958-b755-2b28af3a57d8"},{"cell_type":"code","source":"","metadata":{},"execution_count":null,"outputs":[],"id":"c67afc44-6645-4288-8cdb-a61f73eaecfd"}]}